Traceback (most recent call last):
  File "/Users/jamesasmith/miniconda/envs/gmprocess/lib/python3.8/site-packages/jupyter_cache/executors/utils.py", line 51, in single_nb_execution
    executenb(
  File "/Users/jamesasmith/miniconda/envs/gmprocess/lib/python3.8/site-packages/nbclient/client.py", line 1093, in execute
    return NotebookClient(nb=nb, resources=resources, km=km, **kwargs).execute()
  File "/Users/jamesasmith/miniconda/envs/gmprocess/lib/python3.8/site-packages/nbclient/util.py", line 84, in wrapped
    return just_run(coro(*args, **kwargs))
  File "/Users/jamesasmith/miniconda/envs/gmprocess/lib/python3.8/site-packages/nbclient/util.py", line 62, in just_run
    return loop.run_until_complete(coro)
  File "/Users/jamesasmith/miniconda/envs/gmprocess/lib/python3.8/asyncio/base_events.py", line 616, in run_until_complete
    return future.result()
  File "/Users/jamesasmith/miniconda/envs/gmprocess/lib/python3.8/site-packages/nbclient/client.py", line 559, in async_execute
    await self.async_execute_cell(
  File "/Users/jamesasmith/miniconda/envs/gmprocess/lib/python3.8/site-packages/nbclient/client.py", line 854, in async_execute_cell
    self._check_raise_for_error(cell, exec_reply)
  File "/Users/jamesasmith/miniconda/envs/gmprocess/lib/python3.8/site-packages/nbclient/client.py", line 756, in _check_raise_for_error
    raise CellExecutionError.from_cell_and_msg(cell, exec_reply_content)
nbclient.exceptions.CellExecutionError: An error occurred while executing the following cell:
------------------
rotd_dict = summary.get_imc_dict('ROTD(50.0)')
------------------

[0;31m---------------------------------------------------------------------------[0m
[0;31mAttributeError[0m                            Traceback (most recent call last)
[0;32m/var/folders/y9/prvx92xj1mvg268yxbgl09d1s6v3gn/T/ipykernel_35929/349888471.py[0m in [0;36m<module>[0;34m[0m
[0;32m----> 1[0;31m [0mrotd_dict[0m [0;34m=[0m [0msummary[0m[0;34m.[0m[0mget_imc_dict[0m[0;34m([0m[0;34m'ROTD(50.0)'[0m[0;34m)[0m[0;34m[0m[0;34m[0m[0m
[0m
[0;32m~/Packages/groundmotion-processing/gmprocess/metrics/station_summary.py[0m in [0;36mget_imc_dict[0;34m(self, imc)[0m
[1;32m    883[0m         [0;31m# different IMTs are the different columns.[0m[0;34m[0m[0;34m[0m[0;34m[0m[0m
[1;32m    884[0m         [0;32mfor[0m [0mimc[0m [0;32min[0m [0mimclist[0m[0;34m:[0m[0;34m[0m[0;34m[0m[0m
[0;32m--> 885[0;31m             [0mrow[0m [0;34m=[0m [0m_get_table_row[0m[0;34m([0m[0mself[0m[0;34m.[0m[0m_stream[0m[0;34m,[0m [0mself[0m[0;34m,[0m [0mself[0m[0;34m.[0m[0mevent[0m[0;34m,[0m [0mimc[0m[0;34m)[0m[0;34m[0m[0;34m[0m[0m
[0m[1;32m    886[0m             [0;32mif[0m [0;32mnot[0m [0mlen[0m[0;34m([0m[0mrow[0m[0;34m)[0m[0;34m:[0m[0;34m[0m[0;34m[0m[0m
[1;32m    887[0m                 [0;32mcontinue[0m[0;34m[0m[0;34m[0m[0m

[0;32m~/Packages/groundmotion-processing/gmprocess/utils/tables.py[0m in [0;36m_get_table_row[0;34m(stream, summary, event, imc)[0m
[1;32m    135[0m         [0mrow[0m[0;34m[[0m[0mvs30_dict[0m[0;34m[[0m[0;34m"column_header"[0m[0;34m][0m[0;34m][0m [0;34m=[0m [0mvs30_dict[0m[0;34m[[0m[0;34m"value"[0m[0;34m][0m[0;34m[0m[0;34m[0m[0m
[1;32m    136[0m [0;34m[0m[0m
[0;32m--> 137[0;31m     [0mimt_frame[0m [0;34m=[0m [0msummary[0m[0;34m.[0m[0mpgms[0m[0;34m.[0m[0mxs[0m[0;34m([0m[0mimc[0m[0;34m,[0m [0mlevel[0m[0;34m=[0m[0;36m1[0m[0;34m)[0m[0;34m[0m[0;34m[0m[0m
[0m[1;32m    138[0m     [0mrow[0m[0;34m.[0m[0mupdate[0m[0;34m([0m[0mimt_frame[0m[0;34m.[0m[0mResult[0m[0;34m.[0m[0mto_dict[0m[0;34m([0m[0;34m)[0m[0;34m)[0m[0;34m[0m[0;34m[0m[0m
[1;32m    139[0m     [0;32mreturn[0m [0mrow[0m[0;34m[0m[0;34m[0m[0m

[0;31mAttributeError[0m: 'NoneType' object has no attribute 'xs'
AttributeError: 'NoneType' object has no attribute 'xs'

